#[derive(thiserror::Error, Debug)]
pub enum AuthError {
    #[error("Invalid credentials.")]
    InvalidCredentials(#[source] anyhow::Error),
    #[error(transparent)]
    UnexpectedError(#[from] anyhow::Error),
}

#[derive(thiserror::Error)]
pub enum LoginError {
    #[error("Authentication failed")]
    AuthError(#[source] anyhow::Error),
    #[error("Something went wrong")]
    UnexpectedError(#[from] anyhow::Error),
}

impl std::fmt::Debug for LoginError {
    fn fmt(&self, f: &mut std::fmt::Formatter<'_>) -> std::fmt::Result {
        error_chain_fmt(self, f)
    }
}

pub fn error_chain_fmt(
    e: &impl std::error::Error,
    f: &mut std::fmt::Formatter<'_>,
) -> std::fmt::Result {
    writeln!(f, "{}\n", e)?;
    let mut current = e.source();
    while let Some(cause) = current {
        writeln!(f, "Caused by:\n\t{}", cause)?;
        current = cause.source();
    }
    Ok(())
}
